<robot name="little red rover">
<link name="base_link"></link>
<joint name="base_link_to_base" type="fixed">
<parent link="base_link"/>
<child link="robot_body" />
<origin rpy="0.0 0 0" xyz="0 0 0"/>
</joint>
<link name="robot_body">
<collision>
<origin xyz="-0.086199999999998444533 -0.0002499999999999345736 0.0031300000000001712737" rpy="-4.5796699765772610467e-16 1.0581813203458726654e-16 -9.1593399531631443431e-16" />
<geometry>
<mesh filename="package://little_red_rover/description/rover/skid.stl"/>
</geometry>
</collision>
<collision>
<origin xyz="-0.011299999999998734668 -0.027749999999999955258 -0.011369999999999642545" rpy="-3.141592653589793116 -1.570796326794896336 0" />
<geometry>
<mesh filename="package://little_red_rover/description/rover/tt_motor_mount.stl"/>
</geometry>
</collision>
<collision>
<origin xyz="-0.086199999999998430655 -0.00024999999999993397729 0.004430000000000169913" rpy="3.1415926535897926719 1.0581813203458726654e-16 -9.1593399531631443431e-16" />
<geometry>
<mesh filename="package://little_red_rover/description/rover/motor_attachment_shim.stl"/>
</geometry>
</collision>
<collision>
<origin xyz="-0.011199999999998475064 -0.02774999999999994138 -0.011369999999999826426" rpy="3.1415926535897922278 -1.5707963267948961139 0" />
<geometry>
<mesh filename="package://little_red_rover/description/rover/motor_mount_shim.stl"/>
</geometry>
</collision>
<collision>
<origin xyz="-0.086199999999998444533 -0.00024999999999993441097 0.0034300000000001694585" rpy="-4.5796699765772610467e-16 1.0581813203458726654e-16 -9.1593399531631443431e-16" />
<geometry>
<mesh filename="package://little_red_rover/description/rover/lidar_motor.stl"/>
</geometry>
</collision>
<collision>
<origin xyz="-0.086199999999998444533 -0.00024999999999993441097 0.0034300000000001694585" rpy="-4.5796699765772610467e-16 1.0581813203458726654e-16 -9.1593399531631443431e-16" />
<geometry>
<mesh filename="package://little_red_rover/description/rover/pcb.stl"/>
</geometry>
</collision>
<collision>
<origin xyz="-0.086199999999998444533 -0.00024999999999993441097 0.0034300000000001694585" rpy="-4.5796699765772610467e-16 1.0581813203458726654e-16 -9.1593399531631443431e-16" />
<geometry>
<mesh filename="package://little_red_rover/description/rover/lidar_top.stl"/>
</geometry>
</collision>
<collision>
<origin xyz="-0.011199999999998237407 0.027249999999999829914 -0.011370000000000275719" rpy="3.1415926535897922278 -1.5707963267948961139 0" />
<geometry>
<mesh filename="package://little_red_rover/description/rover/motor_mount_shim.stl"/>
</geometry>
</collision>
<collision>
<origin xyz="-0.086199999999998444533 -0.00024999999999993441097 0.0034300000000001694585" rpy="-4.5796699765772610467e-16 1.0581813203458726654e-16 -9.1593399531631443431e-16" />
<geometry>
<mesh filename="package://little_red_rover/description/rover/motor_attachment_shim.stl"/>
</geometry>
</collision>
<collision>
<origin xyz="-0.011299999999998200373 0.02725000000000004155 -0.011370000000000032858" rpy="3.1415926535897917837 -1.5707963267948961139 0" />
<geometry>
<mesh filename="package://little_red_rover/description/rover/tt_motor_mount.stl"/>
</geometry>
</collision>
<collision>
<origin xyz="-0.011199999999998471595 -0.02774999999999994138 -0.011369999999999826426" rpy="9.1593399531631443431e-16 1.5707963267948961139 0" />
<geometry>
<mesh filename="package://little_red_rover/description/rover/tt_motor_3777_v10.stl"/>
</geometry>
</collision>
<collision>
<origin xyz="-0.011199999999998471595 -0.02774999999999994138 -0.011369999999999826426" rpy="9.1593399531631443431e-16 1.5707963267948961139 0" />
<geometry>
<mesh filename="package://little_red_rover/description/rover/tt_motor_3777_v10.stl"/>
</geometry>
</collision>
<collision>
<origin xyz="-0.011199999999998471595 -0.02774999999999994138 -0.011369999999999826426" rpy="9.1593399531631443431e-16 1.5707963267948961139 0" />
<geometry>
<mesh filename="package://little_red_rover/description/rover/tt_motor_3777_v10.stl"/>
</geometry>
</collision>
<collision>
<origin xyz="-0.011199999999998471595 -0.02774999999999994138 -0.011369999999999826426" rpy="9.1593399531631443431e-16 1.5707963267948961139 0" />
<geometry>
<mesh filename="package://little_red_rover/description/rover/tt_motor_3777_v10.stl"/>
</geometry>
</collision>
<collision>
<origin xyz="-0.011199999999998471595 -0.02774999999999994138 -0.011369999999999826426" rpy="9.1593399531631443431e-16 1.5707963267948961139 0" />
<geometry>
<mesh filename="package://little_red_rover/description/rover/tt_motor_3777_v10.stl"/>
</geometry>
</collision>
<collision>
<origin xyz="-0.011199999999998471595 -0.02774999999999994138 -0.011369999999999826426" rpy="9.1593399531631443431e-16 1.5707963267948961139 0" />
<geometry>
<mesh filename="package://little_red_rover/description/rover/tt_motor_3777_v10.stl"/>
</geometry>
</collision>
<collision>
<origin xyz="-0.011199999999998471595 -0.02774999999999994138 -0.011369999999999826426" rpy="9.1593399531631443431e-16 1.5707963267948961139 0" />
<geometry>
<mesh filename="package://little_red_rover/description/rover/tt_motor_3777_v10.stl"/>
</geometry>
</collision>
<collision>
<origin xyz="-0.011199999999998471595 -0.02774999999999994138 -0.011369999999999826426" rpy="9.1593399531631443431e-16 1.5707963267948961139 0" />
<geometry>
<mesh filename="package://little_red_rover/description/rover/tt_motor_3777_v10.stl"/>
</geometry>
</collision>
<collision>
<origin xyz="-0.011199999999998050057 0.027250000000000010325 -0.011370000000000116125" rpy="3.1415926535897922278 -1.5707963267948961139 0" />
<geometry>
<mesh filename="package://little_red_rover/description/rover/tt_motor_3777_v10.stl"/>
</geometry>
</collision>
<collision>
<origin xyz="-0.011199999999998050057 0.027250000000000010325 -0.011370000000000116125" rpy="3.1415926535897922278 -1.5707963267948961139 0" />
<geometry>
<mesh filename="package://little_red_rover/description/rover/tt_motor_3777_v10.stl"/>
</geometry>
</collision>
<collision>
<origin xyz="-0.011199999999998050057 0.027250000000000010325 -0.011370000000000116125" rpy="3.1415926535897922278 -1.5707963267948961139 0" />
<geometry>
<mesh filename="package://little_red_rover/description/rover/tt_motor_3777_v10.stl"/>
</geometry>
</collision>
<collision>
<origin xyz="-0.011199999999998050057 0.027250000000000010325 -0.011370000000000116125" rpy="3.1415926535897922278 -1.5707963267948961139 0" />
<geometry>
<mesh filename="package://little_red_rover/description/rover/tt_motor_3777_v10.stl"/>
</geometry>
</collision>
<collision>
<origin xyz="-0.011199999999998050057 0.027250000000000010325 -0.011370000000000116125" rpy="3.1415926535897922278 -1.5707963267948961139 0" />
<geometry>
<mesh filename="package://little_red_rover/description/rover/tt_motor_3777_v10.stl"/>
</geometry>
</collision>
<collision>
<origin xyz="-0.011199999999998050057 0.027250000000000010325 -0.011370000000000116125" rpy="3.1415926535897922278 -1.5707963267948961139 0" />
<geometry>
<mesh filename="package://little_red_rover/description/rover/tt_motor_3777_v10.stl"/>
</geometry>
</collision>
<collision>
<origin xyz="-0.011199999999998050057 0.027250000000000010325 -0.011370000000000116125" rpy="3.1415926535897922278 -1.5707963267948961139 0" />
<geometry>
<mesh filename="package://little_red_rover/description/rover/tt_motor_3777_v10.stl"/>
</geometry>
</collision>
<collision>
<origin xyz="-0.011199999999998050057 0.027250000000000010325 -0.011370000000000116125" rpy="3.1415926535897922278 -1.5707963267948961139 0" />
<geometry>
<mesh filename="package://little_red_rover/description/rover/tt_motor_3777_v10.stl"/>
</geometry>
</collision>
<visual>
<origin xyz="0 0 0" rpy="0 -0 0" />
<geometry>
<mesh filename="package://little_red_rover/description/rover/robot_body_visual.stl"/>
</geometry>
<material name="robot_body_material">
<color rgba="0.54609856777458543053 0.54064903973685174421 0.45092154803549289177 1.0"/>
</material>
</visual>
<inertial>
<origin xyz="-0.060449204032374553863 -0.0002507738337924278753 0.0027977271277463983817" rpy="0 0 0"/>
<mass value="0.20115864605429473189" />
<inertia ixx="0.00013884041165555506764" ixy="8.9609098528117574868e-09"  ixz="4.803669073547492662e-05" iyy="0.00028515182973849870132" iyz="-1.8756955665886847784e-09" izz="0.00031707325777148380984" />
</inertial>
</link>

<link name="lidar_frame">
<inertial>
<origin xyz="0 0 0" rpy="0 0 0" />
<mass value="1e-9" />
<inertia ixx="0" ixy="0" ixz="0" iyy="0" iyz="0" izz="0" />
</inertial>
</link>
<joint name="lidar_frame_frame" type="fixed">
<origin xyz="-0.086199999999998278 -0.00024999999999992080424 0.023715000000000173441" rpy="3.1415926535897926719 1.0581813203458726654e-16 -9.1593399531631443431e-16" />
<parent link="robot_body" />
<child link="lidar_frame" />
<axis xyz="0 0 0"/>
</joint>

<link name="wheel_left">
<collision>
<origin xyz="0 3.4694469519536141888e-18 0.027940000000000006497" rpy="3.141592653589793116 -1.4012984643248170709e-45 3.141592653589793116" />
<geometry>
<mesh filename="package://little_red_rover/description/rover/wheel_left.stl"/>
</geometry>
</collision>
<visual>
<origin xyz="0 0 0" rpy="0 -0 0" />
<geometry>
<mesh filename="package://little_red_rover/description/rover/wheel_left_visual.stl"/>
</geometry>
<material name="wheel_left_material">
<color rgba="0.98039215686274505668 0.71372549019607844922 0.0039215686274509803377 1.0"/>
</material>
</visual>
<inertial>
<origin xyz="2.2899368896779690411e-17 5.2743373058211274342e-17 0.014337453204997982134" rpy="0 0 0"/>
<mass value="0.060316879417403129748" />
<inertia ixx="2.3131869643683839843e-05" ixy="0"  ixz="-8.6106979366443999587e-50" iyy="2.3131206012492695268e-05" iyz="0" izz="3.8316124169634606942e-05" />
</inertial>
</link>

<joint name="wheel_left" type="continuous">
<origin xyz="-0.011199999999998485473 -0.042049999999999934652 -0.011369999999999819487" rpy="-1.5707963267948954478 -1.6601303665098055726e-15 -3.141592653589793116" />
<parent link="robot_body" />
<child link="wheel_left" />
<axis xyz="0 0 1"/>
<limit effort="1" velocity="20" />
<joint_properties friction="0.0"/>
</joint>

<link name="wheel_right">
<collision>
<origin xyz="0 1.7347234759768070944e-18 -0.027940000000000003028" rpy="0 3.6207482954353216526e-32 0" />
<geometry>
<mesh filename="package://little_red_rover/description/rover/wheel_right.stl"/>
</geometry>
</collision>
<visual>
<origin xyz="0 0 0" rpy="0 -0 0" />
<geometry>
<mesh filename="package://little_red_rover/description/rover/wheel_right_visual.stl"/>
</geometry>
<material name="wheel_right_material">
<color rgba="0.98039215686274505668 0.71372549019607844922 0.0039215686274509803377 1.0"/>
</material>
</visual>
<inertial>
<origin xyz="-2.2908467087796607425e-17 5.0580625409747609631e-17 0.014337453204998063666" rpy="0 0 0"/>
<mass value="0.06031687941740355996" />
<inertia ixx="2.3131869643683938099e-05" ixy="0"  ixz="2.4093967433908687346e-36" iyy="2.3131206012492813853e-05" iyz="0" izz="3.8316124169634715362e-05" />
</inertial>
</link>

<joint name="wheel_right" type="continuous">
<origin xyz="-0.011199999999998036179 0.041550000000000003597 -0.011370000000000123064" rpy="-1.5707963267948956698 -8.3266726846886296798e-16 -1.3600232051663792198e-15" />
<parent link="robot_body" />
<child link="wheel_right" />
<axis xyz="0 0 1"/>
<limit effort="1" velocity="20" />
<joint_properties friction="0.0"/>
</joint>


</robot>
