<robot name="little red rover">
<link name="base_link"></link>
<joint name="base_link_to_base" type="fixed">
<parent link="base_link"/>
<child link="robot_body" />
<origin rpy="0.0 0 0" xyz="0 0 0"/>
</joint>
<link name="robot_body">
<collision>
<origin xyz="-0.086199999999999998845 -1.2143064331837649661e-17 0.0015000000000000004649" rpy="-1.5265566588595798893e-16 7.9502388104304675625e-31 1.3033732703949976057e-30" />
<geometry>
<mesh filename="http://localhost:8100/skid.stl"/>
</geometry>
</collision>
<collision>
<origin xyz="-0.086200000000000831513 3.8163916471489756077e-17 0.0015000000000000050186" rpy="-4.5796699765786721216e-16 2.3850716431291444726e-30 3.9101198111849427206e-30" />
<geometry>
<mesh filename="http://localhost:8100/motor_mount_shim.stl"/>
</geometry>
</collision>
<collision>
<origin xyz="-0.011299999999997131783 -0.027749999999999875461 -0.011370000000000199392" rpy="-3.141592653589793116 -1.570796326794896336 0" />
<geometry>
<mesh filename="http://localhost:8100/tt_motor_mount.stl"/>
</geometry>
</collision>
<collision>
<origin xyz="-0.011199999999997016162 0.027799999999999876893 -0.011370000000000324292" rpy="-3.141592653589793116 -1.570796326794896558 0" />
<geometry>
<mesh filename="http://localhost:8100/encoder_ring.stl"/>
</geometry>
</collision>
<collision>
<origin xyz="-0.086199999999998500044 -2.8671509610944468173e-17 0.0015000000000000811295" rpy="4.9303806576311792749e-32 3.5032461608119399976e-46 8.6361685550939383751e-78" />
<geometry>
<mesh filename="http://localhost:8100/lidar_motor.stl"/>
</geometry>
</collision>
<collision>
<origin xyz="-0.086199999999999984968 -1.0408340855860842566e-17 0.0025000000000000126288" rpy="3.141592653589793116 7.9502388104304675625e-31 1.3033732703949976057e-30" />
<geometry>
<mesh filename="http://localhost:8100/motor_mount_shim.stl"/>
</geometry>
</collision>
<collision>
<origin xyz="-0.011199999999997394332 -0.027649999999999903821 -0.011370000000000003368" rpy="2.6530262401855620664e-29 1.5707963267948961139 0" />
<geometry>
<mesh filename="http://localhost:8100/encoder_ring.stl"/>
</geometry>
</collision>
<collision>
<origin xyz="-0.011299999999997145661 0.027699999999999894845 -0.011370000000000225412" rpy="3.141592653589793116 -1.570796326794896336 0" />
<geometry>
<mesh filename="http://localhost:8100/tt_motor_mount.stl"/>
</geometry>
</collision>
<collision>
<origin xyz="-0.086199999999999998845 -1.0408340855860842566e-17 0.0014999999999999995975" rpy="-1.5265566588595798893e-16 7.9502388104304675625e-31 1.3033732703949976057e-30" />
<geometry>
<mesh filename="http://localhost:8100/pcb.stl"/>
</geometry>
</collision>
<collision>
<origin xyz="-0.086200000000000026601 -2.7755575615628913511e-17 0.0015000000000000013323" rpy="-4.5796699765786721216e-16 2.3850716431291444726e-30 3.9101198111849427206e-30" />
<geometry>
<mesh filename="http://localhost:8100/lidar_top.stl"/>
</geometry>
</collision>
<collision>
<origin xyz="-0.011199999999997016162 0.027799999999999876893 -0.011370000000000324292" rpy="-6.9068277805714204522e-29 1.570796326794896558 0" />
<geometry>
<mesh filename="http://localhost:8100/tt_motor_3777_v10.stl"/>
</geometry>
</collision>
<collision>
<origin xyz="-0.011199999999997016162 0.027799999999999876893 -0.011370000000000324292" rpy="-6.9068277805714204522e-29 1.570796326794896558 0" />
<geometry>
<mesh filename="http://localhost:8100/tt_motor_3777_v10.stl"/>
</geometry>
</collision>
<collision>
<origin xyz="-0.011199999999997016162 0.027799999999999876893 -0.011370000000000324292" rpy="-6.9068277805714204522e-29 1.570796326794896558 0" />
<geometry>
<mesh filename="http://localhost:8100/tt_motor_3777_v10.stl"/>
</geometry>
</collision>
<collision>
<origin xyz="-0.011199999999997016162 0.027799999999999876893 -0.011370000000000324292" rpy="-6.9068277805714204522e-29 1.570796326794896558 0" />
<geometry>
<mesh filename="http://localhost:8100/tt_motor_3777_v10.stl"/>
</geometry>
</collision>
<collision>
<origin xyz="-0.011199999999997016162 0.027799999999999876893 -0.011370000000000324292" rpy="-6.9068277805714204522e-29 1.570796326794896558 0" />
<geometry>
<mesh filename="http://localhost:8100/tt_motor_3777_v10.stl"/>
</geometry>
</collision>
<collision>
<origin xyz="-0.011199999999997016162 0.027799999999999876893 -0.011370000000000324292" rpy="-6.9068277805714204522e-29 1.570796326794896558 0" />
<geometry>
<mesh filename="http://localhost:8100/tt_motor_3777_v10.stl"/>
</geometry>
</collision>
<collision>
<origin xyz="-0.011199999999997016162 0.027799999999999876893 -0.011370000000000324292" rpy="-6.9068277805714204522e-29 1.570796326794896558 0" />
<geometry>
<mesh filename="http://localhost:8100/tt_motor_3777_v10.stl"/>
</geometry>
</collision>
<collision>
<origin xyz="-0.011199999999997016162 0.027799999999999876893 -0.011370000000000324292" rpy="-6.9068277805714204522e-29 1.570796326794896558 0" />
<geometry>
<mesh filename="http://localhost:8100/tt_motor_3777_v10.stl"/>
</geometry>
</collision>
<collision>
<origin xyz="-0.011199999999997394332 -0.027649999999999862188 -0.011369999999999999898" rpy="3.141592653589793116 -1.570796326794896558 0" />
<geometry>
<mesh filename="http://localhost:8100/tt_motor_3777_v10.stl"/>
</geometry>
</collision>
<collision>
<origin xyz="-0.011199999999997394332 -0.027649999999999862188 -0.011369999999999999898" rpy="3.141592653589793116 -1.570796326794896558 0" />
<geometry>
<mesh filename="http://localhost:8100/tt_motor_3777_v10.stl"/>
</geometry>
</collision>
<collision>
<origin xyz="-0.011199999999997394332 -0.027649999999999862188 -0.011369999999999999898" rpy="3.141592653589793116 -1.570796326794896558 0" />
<geometry>
<mesh filename="http://localhost:8100/tt_motor_3777_v10.stl"/>
</geometry>
</collision>
<collision>
<origin xyz="-0.011199999999997394332 -0.027649999999999862188 -0.011369999999999999898" rpy="3.141592653589793116 -1.570796326794896558 0" />
<geometry>
<mesh filename="http://localhost:8100/tt_motor_3777_v10.stl"/>
</geometry>
</collision>
<collision>
<origin xyz="-0.011199999999997394332 -0.027649999999999862188 -0.011369999999999999898" rpy="3.141592653589793116 -1.570796326794896558 0" />
<geometry>
<mesh filename="http://localhost:8100/tt_motor_3777_v10.stl"/>
</geometry>
</collision>
<collision>
<origin xyz="-0.011199999999997394332 -0.027649999999999862188 -0.011369999999999999898" rpy="3.141592653589793116 -1.570796326794896558 0" />
<geometry>
<mesh filename="http://localhost:8100/tt_motor_3777_v10.stl"/>
</geometry>
</collision>
<collision>
<origin xyz="-0.011199999999997394332 -0.027649999999999862188 -0.011369999999999999898" rpy="3.141592653589793116 -1.570796326794896558 0" />
<geometry>
<mesh filename="http://localhost:8100/tt_motor_3777_v10.stl"/>
</geometry>
</collision>
<collision>
<origin xyz="-0.011199999999997394332 -0.027649999999999862188 -0.011369999999999999898" rpy="3.141592653589793116 -1.570796326794896558 0" />
<geometry>
<mesh filename="http://localhost:8100/tt_motor_3777_v10.stl"/>
</geometry>
</collision>
<visual>
<origin xyz="0 0 0" rpy="0 -0 0" />
<geometry>
<mesh filename="http://localhost:8100/robot_body_visual.stl"/>
</geometry>
<material name="robot_body_material">
<color rgba="0.53195349336139574614 0.52640558069547749298 0.4350762750346341412 1.0"/>
</material>
</visual>
<inertial>
<origin xyz="-0.061074806027640246575 1.9639991023820667506e-05 0.0010370610782280537381" rpy="0 0 0"/>
<mass value="0.19763701795321664267" />
<inertia ixx="0.00013023593072357069855" ixy="-1.0852668512982892053e-07"  ixz="4.3701916069000435079e-05" iyy="0.00027212952606805898385" iyz="4.7189297419103371033e-08" izz="0.00030938951206254972645" />
</inertial>
</link>

<link name="lidar_frame">
<inertial>
<origin xyz="0 0 0" rpy="0 0 0" />
<mass value="1e-9" />
<inertia ixx="0" ixy="0" ixz="0" iyy="0" iyz="0" izz="0" />
</inertial>
</link>
<joint name="lidar_frame_frame" type="fixed">
<origin xyz="-0.086199999999999873945 -3.2250660475519238453e-17 0.020785000000000771608" rpy="3.141592653589793116 -2.8726618518657236517e-44 2.9952754674941379765e-43" />
<parent link="robot_body" />
<child link="lidar_frame" />
<axis xyz="0 0 0"/>
</joint>

<link name="wheel_left">
<collision>
<origin xyz="0 -1.7347234759768070944e-18 -0.027940000000000006497" rpy="0 -6.56858655152258002e-47 3.141592653589793116" />
<geometry>
<mesh filename="http://localhost:8100/wheel_left.stl"/>
</geometry>
</collision>
<visual>
<origin xyz="0 0 0" rpy="0 -0 0" />
<geometry>
<mesh filename="http://localhost:8100/wheel_left_visual.stl"/>
</geometry>
<material name="wheel_left_material">
<color rgba="0.98039215686274505668 0.71372549019607844922 0.0039215686274509803377 1.0"/>
</material>
</visual>
<inertial>
<origin xyz="2.2892270873894273219e-17 -5.1025524127207337716e-17 -0.014337453204997983869" rpy="0 0 0"/>
<mass value="0.060316879417403136687" />
<inertia ixx="2.3131869643683839843e-05" ixy="0"  ixz="-4.8752072508924993928e-51" iyy="2.3131206012492698656e-05" iyz="0" izz="3.8316124169634606942e-05" />
</inertial>
</link>

<joint name="wheel_left_speed" type="continuous">
<origin xyz="-0.011199999999997394332 -0.043149999999999869016 -0.011370000000000001633" rpy="-1.570796326794896558 7.7715611723761046577e-16 -6.4094948549207279255e-31" />
<parent link="robot_body" />
<child link="wheel_left" />
<axis xyz="0 0 1"/>
<limit effort="1" velocity="20" />
<joint_properties friction="0.0"/>
</joint>

<link name="wheel_right">
<collision>
<origin xyz="0 1.7347234759768070944e-18 -0.027940000000000006497" rpy="0 -1.0465947905425977498e-44 0" />
<geometry>
<mesh filename="http://localhost:8100/wheel_right.stl"/>
</geometry>
</collision>
<visual>
<origin xyz="0 0 0" rpy="0 -0 0" />
<geometry>
<mesh filename="http://localhost:8100/wheel_right_visual.stl"/>
</geometry>
<material name="wheel_right_material">
<color rgba="0.98039215686274505668 0.71372549019607844922 0.0039215686274509803377 1.0"/>
</material>
</visual>
<inertial>
<origin xyz="-2.2910676849638288734e-17 5.0597780360105676593e-17 0.014337453204998053258" rpy="0 0 0"/>
<mass value="0.060316879417403580776" />
<inertia ixx="2.3131869643683938099e-05" ixy="0"  ixz="2.4209694264590176959e-49" iyy="2.3131206012492813853e-05" iyz="0" izz="3.8316124169634715362e-05" />
</inertial>
</link>

<joint name="wheel_right_speed" type="continuous">
<origin xyz="-0.011199999999997014427 0.043299999999999880251 -0.011370000000000320822" rpy="1.5707963267948972241 -5.5511151231257728414e-17 -3.141592653589793116" />
<parent link="robot_body" />
<child link="wheel_right" />
<axis xyz="0 0 1"/>
<limit effort="1" velocity="20" />
<joint_properties friction="0.0"/>
</joint>


</robot>
