<robot name="little red rover">
<link name="base_link"></link>
<joint name="base_link_to_base" type="fixed">
<parent link="base_link"/>
<child link="robot_body" />
<origin rpy="0.0 0 0" xyz="0 0 0"/>
</joint>
<link name="robot_body">
<collision>
<origin xyz="-0.086199999999999998845 -1.2143064331837649661e-17 0.0015000000000000004649" rpy="-1.5265566588595798893e-16 7.9502388104304675625e-31 1.3033732703949976057e-30" />
<geometry>
<mesh filename="http://localhost:8100/skid.stl"/>
</geometry>
</collision>
<collision>
<origin xyz="-0.086200000000000831513 3.8163916471489756077e-17 0.0015000000000000050186" rpy="-4.5796699765786721216e-16 2.3850716431291444726e-30 3.9101198111849427206e-30" />
<geometry>
<mesh filename="http://localhost:8100/motor_mount_shim.stl"/>
</geometry>
</collision>
<collision>
<origin xyz="-0.011299999999997131783 -0.027749999999999875461 -0.011370000000000199392" rpy="-3.141592653589793116 -1.570796326794896336 0" />
<geometry>
<mesh filename="http://localhost:8100/tt_motor_mount.stl"/>
</geometry>
</collision>
<collision>
<origin xyz="-0.011199999999997016162 0.027799999999999876893 -0.011370000000000324292" rpy="-3.141592653589793116 -1.570796326794896558 0" />
<geometry>
<mesh filename="http://localhost:8100/encoder_ring.stl"/>
</geometry>
</collision>
<collision>
<origin xyz="-0.086199999999998500044 -2.8671509610944468173e-17 0.0015000000000000811295" rpy="4.9303806576311792749e-32 3.5032461608119399976e-46 8.6361685550939383751e-78" />
<geometry>
<mesh filename="http://localhost:8100/lidar_motor.stl"/>
</geometry>
</collision>
<collision>
<origin xyz="-0.086199999999999984968 -1.0408340855860842566e-17 0.0025000000000000126288" rpy="3.141592653589793116 7.9502388104304675625e-31 1.3033732703949976057e-30" />
<geometry>
<mesh filename="http://localhost:8100/motor_mount_shim.stl"/>
</geometry>
</collision>
<collision>
<origin xyz="-0.011199999999997394332 -0.027649999999999903821 -0.011370000000000003368" rpy="2.6530262401855620664e-29 1.5707963267948961139 0" />
<geometry>
<mesh filename="http://localhost:8100/encoder_ring.stl"/>
</geometry>
</collision>
<collision>
<origin xyz="-0.011299999999997145661 0.027699999999999894845 -0.011370000000000225412" rpy="3.141592653589793116 -1.570796326794896336 0" />
<geometry>
<mesh filename="http://localhost:8100/tt_motor_mount.stl"/>
</geometry>
</collision>
<collision>
<origin xyz="-0.086199999999999998845 -1.0408340855860842566e-17 0.0014999999999999995975" rpy="-1.5265566588595798893e-16 7.9502388104304675625e-31 1.3033732703949976057e-30" />
<geometry>
<mesh filename="http://localhost:8100/pcb.stl"/>
</geometry>
</collision>
<collision>
<origin xyz="-0.086200000000000026601 -2.7755575615628913511e-17 0.0015000000000000013323" rpy="-4.5796699765786721216e-16 2.3850716431291444726e-30 3.9101198111849427206e-30" />
<geometry>
<mesh filename="http://localhost:8100/lidar_top.stl"/>
</geometry>
</collision>
<collision>
<origin xyz="-0.011199999999997016162 0.027799999999999876893 -0.011370000000000324292" rpy="-6.9068277805714204522e-29 1.570796326794896558 0" />
<geometry>
<mesh filename="http://localhost:8100/tt_motor_3777_v10.stl"/>
</geometry>
</collision>
<collision>
<origin xyz="-0.011199999999997016162 0.027799999999999876893 -0.011370000000000324292" rpy="-6.9068277805714204522e-29 1.570796326794896558 0" />
<geometry>
<mesh filename="http://localhost:8100/tt_motor_3777_v10.stl"/>
</geometry>
</collision>
<collision>
<origin xyz="-0.011199999999997016162 0.027799999999999876893 -0.011370000000000324292" rpy="-6.9068277805714204522e-29 1.570796326794896558 0" />
<geometry>
<mesh filename="http://localhost:8100/tt_motor_3777_v10.stl"/>
</geometry>
</collision>
<collision>
<origin xyz="-0.011199999999997016162 0.027799999999999876893 -0.011370000000000324292" rpy="-6.9068277805714204522e-29 1.570796326794896558 0" />
<geometry>
<mesh filename="http://localhost:8100/tt_motor_3777_v10.stl"/>
</geometry>
</collision>
<collision>
<origin xyz="-0.011199999999997016162 0.027799999999999876893 -0.011370000000000324292" rpy="-6.9068277805714204522e-29 1.570796326794896558 0" />
<geometry>
<mesh filename="http://localhost:8100/tt_motor_3777_v10.stl"/>
</geometry>
</collision>
<collision>
<origin xyz="-0.011199999999997016162 0.027799999999999876893 -0.011370000000000324292" rpy="-6.9068277805714204522e-29 1.570796326794896558 0" />
<geometry>
<mesh filename="http://localhost:8100/tt_motor_3777_v10.stl"/>
</geometry>
</collision>
<collision>
<origin xyz="-0.011199999999997016162 0.027799999999999876893 -0.011370000000000324292" rpy="-6.9068277805714204522e-29 1.570796326794896558 0" />
<geometry>
<mesh filename="http://localhost:8100/tt_motor_3777_v10.stl"/>
</geometry>
</collision>
<collision>
<origin xyz="-0.011199999999997016162 0.027799999999999876893 -0.011370000000000324292" rpy="-6.9068277805714204522e-29 1.570796326794896558 0" />
<geometry>
<mesh filename="http://localhost:8100/tt_motor_3777_v10.stl"/>
</geometry>
</collision>
<collision>
<origin xyz="-0.011199999999997394332 -0.027649999999999862188 -0.011369999999999999898" rpy="3.141592653589793116 -1.570796326794896558 0" />
<geometry>
<mesh filename="http://localhost:8100/tt_motor_3777_v10.stl"/>
</geometry>
</collision>
<collision>
<origin xyz="-0.011199999999997394332 -0.027649999999999862188 -0.011369999999999999898" rpy="3.141592653589793116 -1.570796326794896558 0" />
<geometry>
<mesh filename="http://localhost:8100/tt_motor_3777_v10.stl"/>
</geometry>
</collision>
<collision>
<origin xyz="-0.011199999999997394332 -0.027649999999999862188 -0.011369999999999999898" rpy="3.141592653589793116 -1.570796326794896558 0" />
<geometry>
<mesh filename="http://localhost:8100/tt_motor_3777_v10.stl"/>
</geometry>
</collision>
<collision>
<origin xyz="-0.011199999999997394332 -0.027649999999999862188 -0.011369999999999999898" rpy="3.141592653589793116 -1.570796326794896558 0" />
<geometry>
<mesh filename="http://localhost:8100/tt_motor_3777_v10.stl"/>
</geometry>
</collision>
<collision>
<origin xyz="-0.011199999999997394332 -0.027649999999999862188 -0.011369999999999999898" rpy="3.141592653589793116 -1.570796326794896558 0" />
<geometry>
<mesh filename="http://localhost:8100/tt_motor_3777_v10.stl"/>
</geometry>
</collision>
<collision>
<origin xyz="-0.011199999999997394332 -0.027649999999999862188 -0.011369999999999999898" rpy="3.141592653589793116 -1.570796326794896558 0" />
<geometry>
<mesh filename="http://localhost:8100/tt_motor_3777_v10.stl"/>
</geometry>
</collision>
<collision>
<origin xyz="-0.011199999999997394332 -0.027649999999999862188 -0.011369999999999999898" rpy="3.141592653589793116 -1.570796326794896558 0" />
<geometry>
<mesh filename="http://localhost:8100/tt_motor_3777_v10.stl"/>
</geometry>
</collision>
<collision>
<origin xyz="-0.011199999999997394332 -0.027649999999999862188 -0.011369999999999999898" rpy="3.141592653589793116 -1.570796326794896558 0" />
<geometry>
<mesh filename="http://localhost:8100/tt_motor_3777_v10.stl"/>
</geometry>
</collision>
<visual>
<origin xyz="0 0 0" rpy="0 -0 0" />
<geometry>
<mesh filename="http://localhost:8100/robot_body_visual.stl"/>
</geometry>
<material name="robot_body_material">
<color rgba="0.53180996867279028972 0.52626810733991702396 0.43503824126611950751 1.0"/>
</material>
</visual>
<inertial>
<origin xyz="-0.061565968758658065618 1.96187652512886243e-05 0.0010200157400131835278" rpy="0 0 0"/>
<mass value="0.19785237681803841125" />
<inertia ixx="0.00013032668573239632051" ixy="-1.1042952069274321854e-07"  ixz="4.0943477832728155568e-05" iyy="0.00028243241477063325351" iyz="4.7121759764012530934e-08" izz="0.00031966479990597234566" />
</inertial>
</link>

<link name="lidar_frame">
<inertial>
<origin xyz="0 0 0" rpy="0 0 0" />
<mass value="1e-9" />
<inertia ixx="0" ixy="0" ixz="0" iyy="0" iyz="0" izz="0" />
</inertial>
</link>
<joint name="lidar_frame_frame" type="fixed">
<origin xyz="-0.086199999999999873945 -3.2250660475519238453e-17 0.020785000000000775078" rpy="-4.5796699765786721216e-16 2.3850716431291444726e-30 3.9101198111849427206e-30" />
<parent link="robot_body" />
<child link="lidar_frame" />
<axis xyz="0 0 0"/>
</joint>

<link name="wheel_left">
<collision>
<origin xyz="-1.7347234759768070944e-18 0 -0.027940000000000006497" rpy="0 5.2110786642079134825e-45 1.570796326794896558" />
<geometry>
<mesh filename="http://localhost:8100/wheel_left.stl"/>
</geometry>
</collision>
<visual>
<origin xyz="0 0 0" rpy="0 -0 0" />
<geometry>
<mesh filename="http://localhost:8100/wheel_left_visual.stl"/>
</geometry>
<material name="wheel_left_material">
<color rgba="0.98039215686274505668 0.71372549019607844922 0.0039215686274509803377 1.0"/>
</material>
</visual>
<inertial>
<origin xyz="-5.1025864734915426858e-17 -2.290773050051620928e-17 -0.014337453204997983869" rpy="0 0 0"/>
<mass value="0.060316879417403136687" />
<inertia ixx="2.3131206012492695268e-05" ixy="-1.1404565071167936561e-36"  ixz="0" iyy="2.3131869643683839843e-05" iyz="-1.2557564792198217497e-49" izz="3.8316124169634606942e-05" />
</inertial>
</link>

<joint name="wheel_left_speed" type="continuous">
<origin xyz="-0.011199999999997394332 -0.043149999999999820444 -0.011370000000000001633" rpy="-1.570796326794896558 1.570796326794896336 0" />
<parent link="robot_body" />
<child link="wheel_left" />
<axis xyz="0 0 1"/>
<limit effort="1" velocity="20" />
<joint_properties friction="0.0"/>
</joint>

<link name="wheel_right">
<collision>
<origin xyz="0 1.7347234759768070944e-18 -0.027940000000000006497" rpy="0 -1.0465947905425977498e-44 0" />
<geometry>
<mesh filename="http://localhost:8100/wheel_right.stl"/>
</geometry>
</collision>
<visual>
<origin xyz="0 0 0" rpy="0 -0 0" />
<geometry>
<mesh filename="http://localhost:8100/wheel_right_visual.stl"/>
</geometry>
<material name="wheel_right_material">
<color rgba="0.98039215686274505668 0.71372549019607844922 0.0039215686274509803377 1.0"/>
</material>
</visual>
<inertial>
<origin xyz="-2.2905085482554029936e-17 5.058089325966781324e-17 0.014337453204998060197" rpy="0 0 0"/>
<mass value="0.06031687941740355996" />
<inertia ixx="2.3131869643683941487e-05" ixy="0"  ixz="2.4209694264590180757e-49" iyy="2.3131206012492813853e-05" iyz="0" izz="3.8316124169634722138e-05" />
</inertial>
</link>

<joint name="wheel_right_speed" type="continuous">
<origin xyz="-0.011199999999997014427 0.043299999999999880251 -0.011370000000000320822" rpy="1.5707963267948972241 -5.5511151231257728414e-17 -3.141592653589793116" />
<parent link="robot_body" />
<child link="wheel_right" />
<axis xyz="0 0 1"/>
<limit effort="1" velocity="20" />
<joint_properties friction="0.0"/>
</joint>


</robot>
