<robot name="onshape">
<link name="robot_body">
<collision>
<origin xyz="-0.086199999999999998845 -1.2143064331837649661e-17 0.0015000000000000004649" rpy="-1.5265566588595798893e-16 7.9502388104304675625e-31 1.3033732703949976057e-30" />
<geometry>
<mesh filename="package:///skid.stl"/>
</geometry>
</collision>
<collision>
<origin xyz="-0.086200000000000831513 3.8163916471489756077e-17 0.0015000000000000050186" rpy="-4.5796699765786721216e-16 2.3850716431291444726e-30 3.9101198111849427206e-30" />
<geometry>
<mesh filename="package:///motor_mount_shim.stl"/>
</geometry>
</collision>
<collision>
<origin xyz="-0.011199999999999000685 -0.027799999999999866485 -0.011299999999999995812" rpy="-3.141592653589793116 -1.570796326794896336 0" />
<geometry>
<mesh filename="package:///tt_motor_mount_right.stl"/>
</geometry>
</collision>
<collision>
<origin xyz="-0.086199999999998500044 -2.8671509610944468173e-17 0.0015000000000000811295" rpy="4.9303806576311792749e-32 3.5032461608119399976e-46 8.6361685550939383751e-78" />
<geometry>
<mesh filename="package:///lidar_motor.stl"/>
</geometry>
</collision>
<collision>
<origin xyz="-0.086199999999999984968 -1.0408340855860842566e-17 0.0025000000000000126288" rpy="3.141592653589793116 7.9502388104304675625e-31 1.3033732703949976057e-30" />
<geometry>
<mesh filename="package:///motor_mount_shim.stl"/>
</geometry>
</collision>
<collision>
<origin xyz="-0.011199999999999139463 0.050399999999999861577 -0.011300000000000177958" rpy="3.1415926535897926719 -1.570796326794896558 0" />
<geometry>
<mesh filename="package:///tt_motor_mount_left.stl"/>
</geometry>
</collision>
<collision>
<origin xyz="-0.086199999999999998845 -1.0408340855860842566e-17 0.0014999999999999995975" rpy="-1.5265566588595798893e-16 7.9502388104304675625e-31 1.3033732703949976057e-30" />
<geometry>
<mesh filename="package:///pcb.stl"/>
</geometry>
</collision>
<collision>
<origin xyz="-0.086200000000000026601 -2.7755575615628913511e-17 0.0015000000000000013323" rpy="-4.5796699765786721216e-16 2.3850716431291444726e-30 3.9101198111849427206e-30" />
<geometry>
<mesh filename="package:///lidar_top.stl"/>
</geometry>
</collision>
<collision>
<origin xyz="-0.011099999999999141803 0.027899999999999897105 -0.011300000000000174488" rpy="6.4785201841275684203e-29 1.570796326794896558 0" />
<geometry>
<mesh filename="package:///tt_motor_3777_v10.stl"/>
</geometry>
</collision>
<collision>
<origin xyz="-0.011099999999999141803 0.027899999999999897105 -0.011300000000000174488" rpy="6.4785201841275684203e-29 1.570796326794896558 0" />
<geometry>
<mesh filename="package:///tt_motor_3777_v10.stl"/>
</geometry>
</collision>
<collision>
<origin xyz="-0.011099999999999141803 0.027899999999999897105 -0.011300000000000174488" rpy="6.4785201841275684203e-29 1.570796326794896558 0" />
<geometry>
<mesh filename="package:///tt_motor_3777_v10.stl"/>
</geometry>
</collision>
<collision>
<origin xyz="-0.011099999999999141803 0.027899999999999897105 -0.011300000000000174488" rpy="6.4785201841275684203e-29 1.570796326794896558 0" />
<geometry>
<mesh filename="package:///tt_motor_3777_v10.stl"/>
</geometry>
</collision>
<collision>
<origin xyz="-0.011099999999999141803 0.027899999999999897105 -0.011300000000000174488" rpy="6.4785201841275684203e-29 1.570796326794896558 0" />
<geometry>
<mesh filename="package:///tt_motor_3777_v10.stl"/>
</geometry>
</collision>
<collision>
<origin xyz="-0.011099999999999141803 0.027899999999999897105 -0.011300000000000174488" rpy="6.4785201841275684203e-29 1.570796326794896558 0" />
<geometry>
<mesh filename="package:///tt_motor_3777_v10.stl"/>
</geometry>
</collision>
<collision>
<origin xyz="-0.011099999999999141803 0.027899999999999897105 -0.011300000000000174488" rpy="6.4785201841275684203e-29 1.570796326794896558 0" />
<geometry>
<mesh filename="package:///tt_motor_3777_v10.stl"/>
</geometry>
</collision>
<collision>
<origin xyz="-0.011099999999999141803 0.027899999999999897105 -0.011300000000000174488" rpy="6.4785201841275684203e-29 1.570796326794896558 0" />
<geometry>
<mesh filename="package:///tt_motor_3777_v10.stl"/>
</geometry>
</collision>
<collision>
<origin xyz="-0.011099999999998997821 -0.02769999999999986362 -0.011299999999999994077" rpy="-3.141592653589793116 -1.570796326794896336 0" />
<geometry>
<mesh filename="package:///tt_motor_3777_v10.stl"/>
</geometry>
</collision>
<collision>
<origin xyz="-0.011099999999998997821 -0.02769999999999986362 -0.011299999999999994077" rpy="-3.141592653589793116 -1.570796326794896336 0" />
<geometry>
<mesh filename="package:///tt_motor_3777_v10.stl"/>
</geometry>
</collision>
<collision>
<origin xyz="-0.011099999999998997821 -0.02769999999999986362 -0.011299999999999994077" rpy="-3.141592653589793116 -1.570796326794896336 0" />
<geometry>
<mesh filename="package:///tt_motor_3777_v10.stl"/>
</geometry>
</collision>
<collision>
<origin xyz="-0.011099999999998997821 -0.02769999999999986362 -0.011299999999999994077" rpy="-3.141592653589793116 -1.570796326794896336 0" />
<geometry>
<mesh filename="package:///tt_motor_3777_v10.stl"/>
</geometry>
</collision>
<collision>
<origin xyz="-0.011099999999998997821 -0.02769999999999986362 -0.011299999999999994077" rpy="-3.141592653589793116 -1.570796326794896336 0" />
<geometry>
<mesh filename="package:///tt_motor_3777_v10.stl"/>
</geometry>
</collision>
<collision>
<origin xyz="-0.011099999999998997821 -0.02769999999999986362 -0.011299999999999994077" rpy="-3.141592653589793116 -1.570796326794896336 0" />
<geometry>
<mesh filename="package:///tt_motor_3777_v10.stl"/>
</geometry>
</collision>
<collision>
<origin xyz="-0.011099999999998997821 -0.02769999999999986362 -0.011299999999999994077" rpy="-3.141592653589793116 -1.570796326794896336 0" />
<geometry>
<mesh filename="package:///tt_motor_3777_v10.stl"/>
</geometry>
</collision>
<collision>
<origin xyz="-0.011099999999998997821 -0.02769999999999986362 -0.011299999999999994077" rpy="-3.141592653589793116 -1.570796326794896336 0" />
<geometry>
<mesh filename="package:///tt_motor_3777_v10.stl"/>
</geometry>
</collision>
<visual>
<origin xyz="0 0 0" rpy="0 -0 0" />
<geometry>
<mesh filename="package:///robot_body_visual.stl"/>
</geometry>
<material name="robot_body_material">
<color rgba="0.5371264189791425947 0.55491685563194004249 0.43217553011912090977 1.0"/>
</material>
</visual>
<inertial>
<origin xyz="-0.061859315365041023238 2.8446342136623094623e-05 0.0012626480349983554546" rpy="0 0 0"/>
<mass value="0.19644156227102227419" />
<inertia ixx="0.00012884993246987645906" ixy="-1.6981170769165243732e-07"  ixz="3.9403532625537813236e-05" iyy="0.00027884498952463642645" iyz="7.0198032923021002134e-08" izz="0.00031680715070940128905" />
</inertial>
</link>

<link name="wheel">
<collision>
<origin xyz="-1.7347234759768070944e-18 3.4694469519536141888e-18 -0.027940000000000006497" rpy="4.5323247205505802138e-45 -0 0" />
<geometry>
<mesh filename="package:///wheel.stl"/>
</geometry>
</collision>
<visual>
<origin xyz="0 0 0" rpy="0 -0 0" />
<geometry>
<mesh filename="package:///wheel_visual.stl"/>
</geometry>
<material name="wheel_material">
<color rgba="0.98039215686274505668 0.71372549019607844922 0.0039215686274509803377 1.0"/>
</material>
</visual>
<inertial>
<origin xyz="-2.4625119400429648891e-17 5.2761319002864953081e-17 -0.014337453204997983869" rpy="0 0 0"/>
<mass value="0.060316879417403136687" />
<inertia ixx="2.3131869643683829679e-05" ixy="0"  ixz="0" iyy="2.3131206012492695268e-05" iyz="8.3445100702762721499e-50" izz="3.8316124169634593389e-05" />
</inertial>
</link>

<joint name="wheel_right_speed" type="continuous">
<origin xyz="-0.011099999999998997821 -0.043199999999999863509 -0.011299999999999992342" rpy="-1.570796326794896558 -1.570796326794896336 0" />
<parent link="robot_body" />
<child link="wheel" />
<axis xyz="0 0 1"/>
<limit effort="1" velocity="20" />
<joint_properties friction="0.0"/>
</joint>

<link name="wheel_2">
<collision>
<origin xyz="0 -1.7347234759768070944e-18 0.027940000000000020375" rpy="3.141592653589793116 -1.019518080370513794e-45 0" />
<geometry>
<mesh filename="package:///wheel.stl"/>
</geometry>
</collision>
<visual>
<origin xyz="0 0 0" rpy="0 -0 0" />
<geometry>
<mesh filename="package:///wheel_2_visual.stl"/>
</geometry>
<material name="wheel_2_material">
<color rgba="0.98039215686274505668 0.71372549019607844922 0.0039215686274509803377 1.0"/>
</material>
</visual>
<inertial>
<origin xyz="-2.2890395924452841797e-17 -5.1026595526888152149e-17 0.014337453204997997747" rpy="0 0 0"/>
<mass value="0.060316879417403136687" />
<inertia ixx="2.3131869643683829679e-05" ixy="0"  ixz="6.264734069517384396e-50" iyy="2.3131206012492695268e-05" iyz="0" izz="3.8316124169634593389e-05" />
</inertial>
</link>

<joint name="wheel_left_speed" type="continuous">
<origin xyz="-0.011099999999999141803 0.043399999999999938627 -0.011300000000000167549" rpy="1.5707963267948970021 -2.2261824227171183414e-30 3.141592653589793116" />
<parent link="robot_body" />
<child link="wheel_2" />
<axis xyz="0 0 1"/>
<limit effort="1" velocity="20" />
<joint_properties friction="0.0"/>
</joint>


</robot>
